Traceback (most recent call last):
  File "/home/ben/miniconda3/envs/pyCATHY_doc/lib/python3.10/site-packages/jupyter_cache/executors/utils.py", line 58, in single_nb_execution
    executenb(
  File "/home/ben/miniconda3/envs/pyCATHY_doc/lib/python3.10/site-packages/nbclient/client.py", line 1204, in execute
    return NotebookClient(nb=nb, resources=resources, km=km, **kwargs).execute()
  File "/home/ben/miniconda3/envs/pyCATHY_doc/lib/python3.10/site-packages/nbclient/util.py", line 84, in wrapped
    return just_run(coro(*args, **kwargs))
  File "/home/ben/miniconda3/envs/pyCATHY_doc/lib/python3.10/site-packages/nbclient/util.py", line 62, in just_run
    return loop.run_until_complete(coro)
  File "/home/ben/miniconda3/envs/pyCATHY_doc/lib/python3.10/asyncio/base_events.py", line 649, in run_until_complete
    return future.result()
  File "/home/ben/miniconda3/envs/pyCATHY_doc/lib/python3.10/site-packages/nbclient/client.py", line 663, in async_execute
    await self.async_execute_cell(
  File "/home/ben/miniconda3/envs/pyCATHY_doc/lib/python3.10/site-packages/nbclient/client.py", line 965, in async_execute_cell
    await self._check_raise_for_error(cell, cell_index, exec_reply)
  File "/home/ben/miniconda3/envs/pyCATHY_doc/lib/python3.10/site-packages/nbclient/client.py", line 862, in _check_raise_for_error
    raise CellExecutionError.from_cell_and_msg(cell, exec_reply_content)
nbclient.exceptions.CellExecutionError: An error occurred while executing the following cell:
------------------
simu.update_atmbc(
                    HSPATM=1,
                    IETO=0,
                    time=df_atmbc_hourly['time'],
                    netValue=df_atmbc_hourly['value'],
)
simu.show_input('atmbc')
------------------

[0;31m---------------------------------------------------------------------------[0m
[0;31mValueError[0m                                Traceback (most recent call last)
File [0;32m~/miniconda3/envs/pyCATHY_doc/lib/python3.10/site-packages/pandas/core/indexes/range.py:345[0m, in [0;36mRangeIndex.get_loc[0;34m(self, key)[0m
[1;32m    344[0m [38;5;28;01mtry[39;00m:
[0;32m--> 345[0m     [38;5;28;01mreturn[39;00m [38;5;28;43mself[39;49m[38;5;241;43m.[39;49m[43m_range[49m[38;5;241;43m.[39;49m[43mindex[49m[43m([49m[43mnew_key[49m[43m)[49m
[1;32m    346[0m [38;5;28;01mexcept[39;00m [38;5;167;01mValueError[39;00m [38;5;28;01mas[39;00m err:

[0;31mValueError[0m: -1 is not in range

The above exception was the direct cause of the following exception:

[0;31mKeyError[0m                                  Traceback (most recent call last)
Cell [0;32mIn[12], line 1[0m
[0;32m----> 1[0m [43msimu[49m[38;5;241;43m.[39;49m[43mupdate_atmbc[49m[43m([49m
[1;32m      2[0m [43m                    [49m[43mHSPATM[49m[38;5;241;43m=[39;49m[38;5;241;43m1[39;49m[43m,[49m
[1;32m      3[0m [43m                    [49m[43mIETO[49m[38;5;241;43m=[39;49m[38;5;241;43m0[39;49m[43m,[49m
[1;32m      4[0m [43m                    [49m[43mtime[49m[38;5;241;43m=[39;49m[43mdf_atmbc_hourly[49m[43m[[49m[38;5;124;43m'[39;49m[38;5;124;43mtime[39;49m[38;5;124;43m'[39;49m[43m][49m[43m,[49m
[1;32m      5[0m [43m                    [49m[43mnetValue[49m[38;5;241;43m=[39;49m[43mdf_atmbc_hourly[49m[43m[[49m[38;5;124;43m'[39;49m[38;5;124;43mvalue[39;49m[38;5;124;43m'[39;49m[43m][49m[43m,[49m
[1;32m      6[0m [43m)[49m
[1;32m      7[0m simu[38;5;241m.[39mshow_input([38;5;124m'[39m[38;5;124matmbc[39m[38;5;124m'[39m)

File [0;32m~/Documents/GitHub/BenjMy/pycathy_wrapper/pyCATHY/cathy_tools.py:1850[0m, in [0;36mCATHY.update_atmbc[0;34m(self, HSPATM, IETO, time, VALUE, netValue, show, verbose, **kwargs)[0m
[1;32m   1846[0m             np[38;5;241m.[39msavetxt(atmbcfile, v, fmt[38;5;241m=[39m[38;5;124m"[39m[38;5;132;01m%.3e[39;00m[38;5;124m"[39m)
[1;32m   1848[0m atmbcfile[38;5;241m.[39mclose()
[0;32m-> 1850[0m [38;5;28mself[39m[38;5;241m.[39mupdate_parm(TIMPRTi[38;5;241m=[39m[time[[38;5;241m0[39m],[43mtime[49m[43m[[49m[38;5;241;43m-[39;49m[38;5;241;43m1[39;49m[43m][49m], NPRT[38;5;241m=[39m[38;5;241m2[39m, TMAX[38;5;241m=[39m[38;5;28mmax[39m(time))
[1;32m   1851[0m [38;5;66;03m# self.update_parm(TIMPRTi=time, NPRT=len(time), TMAX=max(time))[39;00m
[1;32m   1852[0m 
[1;32m   1853[0m [38;5;66;03m# don't need to update if sequential DA as the cathy.exe is already created[39;00m
[1;32m   1854[0m [38;5;66;03m# ---------------------------------------------------------------------[39;00m
[1;32m   1855[0m [38;5;28;01mif[39;00m [38;5;124m"[39m[38;5;124momit_cathyH[39m[38;5;124m"[39m [38;5;129;01mnot[39;00m [38;5;129;01min[39;00m kwargs:

File [0;32m~/miniconda3/envs/pyCATHY_doc/lib/python3.10/site-packages/pandas/core/series.py:1007[0m, in [0;36mSeries.__getitem__[0;34m(self, key)[0m
[1;32m   1004[0m     [38;5;28;01mreturn[39;00m [38;5;28mself[39m[38;5;241m.[39m_values[key]
[1;32m   1006[0m [38;5;28;01melif[39;00m key_is_scalar:
[0;32m-> 1007[0m     [38;5;28;01mreturn[39;00m [38;5;28;43mself[39;49m[38;5;241;43m.[39;49m[43m_get_value[49m[43m([49m[43mkey[49m[43m)[49m
[1;32m   1009[0m [38;5;28;01mif[39;00m is_hashable(key):
[1;32m   1010[0m     [38;5;66;03m# Otherwise index.get_value will raise InvalidIndexError[39;00m
[1;32m   1011[0m     [38;5;28;01mtry[39;00m:
[1;32m   1012[0m         [38;5;66;03m# For labels that don't resolve as scalars like tuples and frozensets[39;00m

File [0;32m~/miniconda3/envs/pyCATHY_doc/lib/python3.10/site-packages/pandas/core/series.py:1116[0m, in [0;36mSeries._get_value[0;34m(self, label, takeable)[0m
[1;32m   1113[0m     [38;5;28;01mreturn[39;00m [38;5;28mself[39m[38;5;241m.[39m_values[label]
[1;32m   1115[0m [38;5;66;03m# Similar to Index.get_value, but we do not fall back to positional[39;00m
[0;32m-> 1116[0m loc [38;5;241m=[39m [38;5;28;43mself[39;49m[38;5;241;43m.[39;49m[43mindex[49m[38;5;241;43m.[39;49m[43mget_loc[49m[43m([49m[43mlabel[49m[43m)[49m
[1;32m   1118[0m [38;5;28;01mif[39;00m is_integer(loc):
[1;32m   1119[0m     [38;5;28;01mreturn[39;00m [38;5;28mself[39m[38;5;241m.[39m_values[loc]

File [0;32m~/miniconda3/envs/pyCATHY_doc/lib/python3.10/site-packages/pandas/core/indexes/range.py:347[0m, in [0;36mRangeIndex.get_loc[0;34m(self, key)[0m
[1;32m    345[0m         [38;5;28;01mreturn[39;00m [38;5;28mself[39m[38;5;241m.[39m_range[38;5;241m.[39mindex(new_key)
[1;32m    346[0m     [38;5;28;01mexcept[39;00m [38;5;167;01mValueError[39;00m [38;5;28;01mas[39;00m err:
[0;32m--> 347[0m         [38;5;28;01mraise[39;00m [38;5;167;01mKeyError[39;00m(key) [38;5;28;01mfrom[39;00m [38;5;21;01merr[39;00m
[1;32m    348[0m [38;5;28;01mif[39;00m [38;5;28misinstance[39m(key, Hashable):
[1;32m    349[0m     [38;5;28;01mraise[39;00m [38;5;167;01mKeyError[39;00m(key)

[0;31mKeyError[0m: -1
KeyError: -1

