Traceback (most recent call last):
  File "/home/z0272571a@CAMPUS.CSIC.ES/miniconda3/envs/pyCATHY_doc/lib/python3.10/site-packages/nbclient/client.py", line 782, in _async_poll_for_reply
    msg = await ensure_async(self.kc.shell_channel.get_msg(timeout=new_timeout))
  File "/home/z0272571a@CAMPUS.CSIC.ES/miniconda3/envs/pyCATHY_doc/lib/python3.10/site-packages/jupyter_core/utils/__init__.py", line 198, in ensure_async
    result = await obj
  File "/home/z0272571a@CAMPUS.CSIC.ES/miniconda3/envs/pyCATHY_doc/lib/python3.10/site-packages/jupyter_client/channels.py", line 315, in get_msg
    raise Empty
_queue.Empty

During handling of the above exception, another exception occurred:

Traceback (most recent call last):
  File "/home/z0272571a@CAMPUS.CSIC.ES/miniconda3/envs/pyCATHY_doc/lib/python3.10/site-packages/jupyter_cache/executors/utils.py", line 58, in single_nb_execution
    executenb(
  File "/home/z0272571a@CAMPUS.CSIC.ES/miniconda3/envs/pyCATHY_doc/lib/python3.10/site-packages/nbclient/client.py", line 1314, in execute
    return NotebookClient(nb=nb, resources=resources, km=km, **kwargs).execute()
  File "/home/z0272571a@CAMPUS.CSIC.ES/miniconda3/envs/pyCATHY_doc/lib/python3.10/site-packages/jupyter_core/utils/__init__.py", line 165, in wrapped
    return loop.run_until_complete(inner)
  File "/home/z0272571a@CAMPUS.CSIC.ES/miniconda3/envs/pyCATHY_doc/lib/python3.10/asyncio/base_events.py", line 649, in run_until_complete
    return future.result()
  File "/home/z0272571a@CAMPUS.CSIC.ES/miniconda3/envs/pyCATHY_doc/lib/python3.10/site-packages/nbclient/client.py", line 709, in async_execute
    await self.async_execute_cell(
  File "/home/z0272571a@CAMPUS.CSIC.ES/miniconda3/envs/pyCATHY_doc/lib/python3.10/site-packages/nbclient/client.py", line 1005, in async_execute_cell
    exec_reply = await self.task_poll_for_reply
  File "/home/z0272571a@CAMPUS.CSIC.ES/miniconda3/envs/pyCATHY_doc/lib/python3.10/site-packages/nbclient/client.py", line 806, in _async_poll_for_reply
    error_on_timeout_execute_reply = await self._async_handle_timeout(timeout, cell)
  File "/home/z0272571a@CAMPUS.CSIC.ES/miniconda3/envs/pyCATHY_doc/lib/python3.10/site-packages/nbclient/client.py", line 856, in _async_handle_timeout
    raise CellTimeoutError.error_from_timeout_and_cell(
nbclient.exceptions.CellTimeoutError: A cell timed out while it was being executed, after 30 seconds.
The message was: Cell execution timed out.
Here is a preview of the cell contents:
-------------------
['prj_name = "test0"', 'path2prj = "weil_exemple_sensitivityAnalysis"  # add your local path here', 'simu = cathy_tools.CATHY(', '    dirName=path2prj, prj_name=prj_name, clear_src=False, clear_outputs=True', ')']
...
['dpsi = simu.read_outputs("psi")', 'dsw, _ = simu.read_outputs("sw")', '', 'obs_data = np.hstack(dsw)', 'len(obs_data)']
-------------------

