Traceback (most recent call last):
  File "/home/z0272571a@CAMPUS.CSIC.ES/miniconda3/envs/pyCATHY_doc/lib/python3.10/site-packages/jupyter_cache/executors/utils.py", line 58, in single_nb_execution
    executenb(
  File "/home/z0272571a@CAMPUS.CSIC.ES/miniconda3/envs/pyCATHY_doc/lib/python3.10/site-packages/nbclient/client.py", line 1314, in execute
    return NotebookClient(nb=nb, resources=resources, km=km, **kwargs).execute()
  File "/home/z0272571a@CAMPUS.CSIC.ES/miniconda3/envs/pyCATHY_doc/lib/python3.10/site-packages/jupyter_core/utils/__init__.py", line 165, in wrapped
    return loop.run_until_complete(inner)
  File "/home/z0272571a@CAMPUS.CSIC.ES/miniconda3/envs/pyCATHY_doc/lib/python3.10/asyncio/base_events.py", line 649, in run_until_complete
    return future.result()
  File "/home/z0272571a@CAMPUS.CSIC.ES/miniconda3/envs/pyCATHY_doc/lib/python3.10/site-packages/nbclient/client.py", line 709, in async_execute
    await self.async_execute_cell(
  File "/home/z0272571a@CAMPUS.CSIC.ES/miniconda3/envs/pyCATHY_doc/lib/python3.10/site-packages/nbclient/client.py", line 1062, in async_execute_cell
    await self._check_raise_for_error(cell, cell_index, exec_reply)
  File "/home/z0272571a@CAMPUS.CSIC.ES/miniconda3/envs/pyCATHY_doc/lib/python3.10/site-packages/nbclient/client.py", line 918, in _check_raise_for_error
    raise CellExecutionError.from_cell_and_msg(cell, exec_reply_content)
nbclient.exceptions.CellExecutionError: An error occurred while executing the following cell:
------------------
import os
import matplotlib.pyplot as plt
from pyCATHY.DA.cathy_DA import DA
from pyCATHY.DA import perturbate
from pyCATHY.DA.cathy_DA import perturbate_parm, dictObs_2pd
from pyCATHY.DA.observations import read_observations, prepare_observations, make_data_cov
------------------


[0;31m---------------------------------------------------------------------------[0m
[0;31mImportError[0m                               Traceback (most recent call last)
Cell [0;32mIn[1], line 5[0m
[1;32m      3[0m [38;5;28;01mfrom[39;00m [38;5;21;01mpyCATHY[39;00m[38;5;21;01m.[39;00m[38;5;21;01mDA[39;00m[38;5;21;01m.[39;00m[38;5;21;01mcathy_DA[39;00m [38;5;28;01mimport[39;00m DA
[1;32m      4[0m [38;5;28;01mfrom[39;00m [38;5;21;01mpyCATHY[39;00m[38;5;21;01m.[39;00m[38;5;21;01mDA[39;00m [38;5;28;01mimport[39;00m perturbate
[0;32m----> 5[0m [38;5;28;01mfrom[39;00m [38;5;21;01mpyCATHY[39;00m[38;5;21;01m.[39;00m[38;5;21;01mDA[39;00m[38;5;21;01m.[39;00m[38;5;21;01mcathy_DA[39;00m [38;5;28;01mimport[39;00m perturbate_parm, dictObs_2pd
[1;32m      6[0m [38;5;28;01mfrom[39;00m [38;5;21;01mpyCATHY[39;00m[38;5;21;01m.[39;00m[38;5;21;01mDA[39;00m[38;5;21;01m.[39;00m[38;5;21;01mobservations[39;00m [38;5;28;01mimport[39;00m read_observations, prepare_observations, make_data_cov

[0;31mImportError[0m: cannot import name 'perturbate_parm' from 'pyCATHY.DA.cathy_DA' (/home/z0272571a@CAMPUS.CSIC.ES/miniconda3/envs/pyCATHY_doc/lib/python3.10/site-packages/pyCATHY-0.1.1-py3.10.egg/pyCATHY/DA/cathy_DA.py)

